Workbook

Sheet User Guide
A1: 📘 USER GUIDE — Singapore Property Leverage Optimizer
B3: WHAT THIS WORKBOOK DOES
B4: This workbook helps you decide whether to buy property in Singapore — and which type — by comparing 6 property scenarios against a pure investment portfolio ("No Property" benchmark). It models a 20-year horizon and accounts for:
B5: • Mortgage leverage (75% LTV) with SORA-based interest rates
B6: • Leasehold decay using SLA Bala’s Table (critical for HDB & 99-year condos)
B7: • CPF OA usage and accrued interest you must repay on sale
B8: • Transaction costs (BSD, ABSD, legal fees, agent fees)
B9: • Imputed rent savings (owner-occupied) or rental income (investment mode)
B10: • Opportunity cost: what your cash would have grown to in a 60/40 portfolio instead
B11: • Interest rate stress testing (Base / Stress / Severe SORA scenarios)
B13: The 6 property types compared:
B14: 1. HDB 1984 — Older resale HDB (57-year lease remaining), lowest entry cost but highest lease decay risk
B15: 2. HDB 2005 — Mid-age resale HDB (78-year lease), moderate decay
... B23: Change values in the Assumptions sheet and the entire model recalculates automatically across all 14 sheets.
A25: STEP 1 | B25: Enter Your Investor Profile (Assumptions sheet, rows 4–10) | E25: Your Value ✏️
B26: Cell | C26: What to Enter | D26: Guidance | E26: ← Type here (auto-syncs to model)
B27: Assumptions!C4 | C27: Your current age (e.g., 32) | D27: This determines your exit age. Exit Age = Current Age + Analysis Horizon. | E27: 32
B28: Assumptions!C5 | C28: Analysis horizon in years (e.g., 30) | D28: How many years to project. The property sheets show 20-year detail; this sets the overall planning window. | E28: 30
B29: Assumptions!C7 | C29: Your total net worth in SGD (e.g., 800,000) | D29: Include all liquid savings + CPF OA. This is the total capital pool the model allocates between property and investments. | E29: 800000
B30: Assumptions!C8 | C30: Your CPF OA balance (e.g., 150,000) | D30: Amount of CPF OA you will use for the downpayment. Must be ≤ Total Net Worth. CPF accrued interest (2.5%) must be repaid when you sell. | E30: 150000
B31: Assumptions!C9 | C31: CPF OA interest rate (default 2.5%) | D31: Currently 2.5% p.a. from CPF Board. Only change if policy changes. | E31: 0.025
B32: Assumptions!C10 | C32: Residency status (DROPDOWN) | D32: Choose: "SC 1st Property" (0% ABSD), "SC 2nd Property" (20% ABSD), or "PR" (5% ABSD). This changes ABSD across all properties. | E32: SC 1st Property
C33: → C6 (Exit Age) is auto-calculated. Do NOT type in it.
A35: STEP 2 | B35: Set Your Interest Rate Scenario (Assumptions sheet, rows 13–19) | E35: Your Value ✏️
B36: Cell | C36: What to Enter | D36: Guidance | E36: ← Type here (auto-syncs to model)
B37: Assumptions!C13 | C37: 6M Compounded SORA (e.g., 1.221%) | D37: Look up the latest rate from MAS. Pre-filled with Feb 2026 rate. This feeds the Base mortgage rate. | E37: 0.01221
B38: Assumptions!C14 | C38: Bank spread (e.g., 0.45%) | D38: Your bank's quoted spread above SORA. Typical SG banks: 0.40%–0.55%. Base rate = SORA + Spread (auto-calculated in C15). | E38: 0.0045
B39: Assumptions!C16 | C39: Stress mortgage rate (e.g., 3.5%) | D39: A moderately adverse rate scenario. Used when you switch to "Stress" in C18. | E39: 0.035
B40: Assumptions!C17 | C40: Severe mortgage rate (e.g., 5.0%) | D40: Worst-case rate scenario. Useful for stress-testing affordability. | E40: 0.05
B41: Assumptions!C18 | C41: Active Rate Scenario (DROPDOWN) | D41: Choose: "Base" / "Stress" / "Severe". This switches the mortgage rate used in all calculations. The effective rate appears in C19. | E41: Base
C42: → C15 (All-in Base Rate) and C19 (Effective Rate) are formulas. Do NOT type in them.
C43: → Note: HDB loans use a fixed 2.6% (CPF rate). Only private property rates change with this dropdown.
A45: STEP 3 | B45: Adjust Leverage & Financing (Assumptions sheet, rows 22–27) | E45: Your Value ✏️
B46: Cell | C46: What to Enter | D46: Guidance | E46: ← Type here (auto-syncs to model)
B47: Assumptions!C22 | C47: LTV Ratio (default 75%) | D47: Maximum LTV in SG is 75% for first property. Downpayment % (C23) auto-calculates as 1 – LTV. | E47: 0.75
B48: Assumptions!C24 | C48: CPF usage for downpayment (default 20%) | D48: % of property price paid from CPF OA. Cash downpayment (C25) = Total downpayment – CPF usage. | E48: 0.2
B49: Assumptions!C26 | C49: Mortgage tenure in years (e.g., 30) | D49: Range: 15–35 years. Longer tenure = lower monthly payment but more interest. Max age at loan maturity is 65 (bank) or 75 (HDB). | E49: 30
C50: → C23 (Downpayment %), C25 (Cash DP %), and C27 (Leverage Multiple) are all formulas.
A53: STEP 4 | B53: Customize Property Details (Assumptions sheet, rows 31–43) | E53: Your Value ✏️
B54: Cell | C54: What to Enter | D54: Guidance | E54: ← Type here (auto-syncs to model)
...

Sheet Assumptions
A1: SINGAPORE PROPERTY LEVERAGE OPTIMIZER — ASSUMPTIONS
A3: INVESTOR PROFILE
A4: Current Age | C4: ='User Guide'!E27 -> 32 | D4: years
A5: Analysis Horizon | C5: ='User Guide'!E28 -> 30 | D5: years
A6: Exit Age | C6: =C4+C5 -> 62 | D6: years
A7: Total Net Worth | C7: ='User Guide'!E29 -> 800000
A8: CPF OA Balance | C8: ='User Guide'!E30 -> 150000 | D8: ← Edit via User Guide sheet
A9: CPF OA Interest Rate | C9: ='User Guide'!E31 -> 0.025
A10: Residency Status | C10: ='User Guide'!E32 -> SC 1st Property | D10: ← Dropdown
A12: MARKET RATES (LIVE DATA — Feb 2026)
A13: 6M Compounded SORA | C13: ='User Guide'!E37 -> 0.01221
A14: Bank Spread | C14: ='User Guide'!E38 -> 0.0045
A15: All-in Mortgage Rate (Base) | C15: =C13+C14 -> 0.01671 | D15: SORA + Spread
A16: Stress Mortgage Rate | C16: ='User Guide'!E39 -> 0.035
A17: Severe Mortgage Rate | C17: ='User Guide'!E40 -> 0.05
A18: Active Rate Scenario | C18: ='User Guide'!E41 -> Base | D18: ← Dropdown: Base / Stress / Severe
A19: Effective Mortgage Rate | C19: =INDEX('Scenario Tables'!C$24:C$26,MATCH(C18,'Scenario Tables'!$A$24:$A$26,0)) -> 0.026 | D19: ← Used in all calcs
A21: LEVERAGE & FINANCING
A22: LTV Ratio | C22: ='User Guide'!E47 -> 0.75
A23: Downpayment % | C23: =1-C22 -> 0.25
A24: CPF Usage for Downpayment % | C24: ='User Guide'!E48 -> 0.2 | D24: of property price
A25: Cash Downpayment % | C25: =C23-C24 -> 0.05 | D25: of property price
A26: Mortgage Tenure (years) | C26: ='User Guide'!E49 -> 30 | D26: ← Flexible: 15-35
A27: Leverage Multiple | C27: =1/C23 -> 4
A29: PROPERTY ASSUMPTIONS | F29: PROPERTY ASSUMPTIONS | G29: PROPERTY ASSUMPTIONS | H29: PROPERTY ASSUMPTIONS
C30: HDB 1984 | D30: Condo 99LH | E30: FH Condo | F30: HDB 2005 | G30: HDB 2015 | H30: FH Landed (Prime)
A31: Purchase Price | C31: 1400000 | D31: 2500000 | E31: 3900000 | F31: 780000 | G31: 1400000 | H31: 7000000
A32: PSF ($) | C32: 885 | D32: 1800 | E32: 2600 | F32: 650 | G32: 1200 | H32: 1556
A33: Remaining Lease (years) | C33: 57 | D33: 93 | E33: Freehold | F33: 78 | G33: 88 | H33: 999
A34: Land Appreciation Scenario | B34: Custom | C34: =INDEX('Scenario Tables'!C$5:C$8,MATCH(B34,'Scenario Tables'!$A$5:$A$8,0)) -> 0.02 | D34: =INDEX('Scenario Tables'!D$5:D$8,MATCH(B34,'Scenario Tables'!$A$5:$A$8,0)) -> 0.03 | E34: =INDEX('Scenario Tables'!E$5:E$8,MATCH(B34,'Scenario Tables'!$A$5:$A$8,0)) -> 0.04 | F34: =INDEX('Scenario Tables'!F$5:F$8,MATCH(B34,'Scenario Tables'!$A$5:$A$8,0)) -> 0.03 | G34: =INDEX('Scenario Tables'!G$5:G$8,MATCH(B34,'Scenario Tables'!$A$5:$A$8,0)) -> 0.03 | H34: =INDEX('Scenario Tables'!H$5:H$8,MATCH(B34,'Scenario Tables'!$A$5:$A$8,0)) -> 0.05
A35: Monthly Imputed Rent | C35: 4500 | D35: 5200 | E35: 8200 | F35: 4500 | G35: 4500 | H35: 15000
A36: Annual Rent Growth | C36: 0.02 | D36: 0.02 | E36: 0.02 | F36: 0.02 | G36: 0.02 | H36: 0.02
A37: Annual Maintenance/Condo Fee (Yr1) | C37: 1080 | D37: 6000 | E37: 8400 | F37: 1200 | G37: 1320 | H37: 18000
A38: Property Tax Method | C38: IRAS Progressive on AV | D38: IRAS Progressive on AV | E38: IRAS Progressive on AV | F38: IRAS Progressive on AV | G38: IRAS Progressive on AV | H38: IRAS Progressive on AV
A39: Usage Mode | C39: ='User Guide'!E62 -> Owner-Occupied
A40: Vacancy Rate (% annual) | C40: 0.0833 | D40: ← Investment only
A41: Property Mgmt Fee (% of rent) | C41: 0.1 | D41: ← Investment only
A42: Rental Income Tax Rate | C42: 0.15 | D42: ← Investment only
A43: General Inflation Rate | C43: ='User Guide'!E64 -> 0.025 | D43: ← Real return calc
A45: TRANSACTION COSTS
...

Sheet Dashboard
A1: LEVERAGED PROPERTY ANALYSIS — EXECUTIVE DASHBOARD
A3: ACTIVE SCENARIO
A4: Residency Status | C4: =Assumptions!C10 -> SC 1st Property | G4: Rate Scenario | I4: =Assumptions!C18 -> Base
A5: Effective Mortgage Rate | C5: =Assumptions!C19 -> 0.026 | G5: Mortgage Tenure | I5: =Assumptions!C26 -> 30
A6: Investor Net Worth | C6: =Assumptions!C7 -> 800000 | G6: Analysis Horizon | I6: =Assumptions!C5 -> 30
A7: Benchmark Portfolio CAGR | C7: =Assumptions!C54 -> 0.055
A9: PROPERTY COMPARISON (20-YEAR TERMINAL VALUES)
C10: HDB 1984 | D10: HDB 2005 | E10: HDB 2015 | F10: Condo 99LH | G10: FH Condo | H10: No Property | I10: FH Landed
A11: PURCHASE & CAPITAL
A12: Purchase Price | C12: ='HDB 1984'!C4 -> 1400000 | D12: ='HDB 2005'!C4 -> 780000 | E12: ='HDB 2015'!C4 -> 1400000 | F12: ='Condo 99LH'!C4 -> 2500000 | G12: ='FH Condo'!C4 -> 3900000 | H12: - | I12: ='FH Landed (Prime)'!C4 -> 7000000
A13: Total Cash Outlay (Day 1) | C13: ='HDB 1984'!C9 -> 262200 | D13: ='HDB 2005'!C9 -> 72200 | E13: ='HDB 2015'!C9 -> 262200 | F13: ='Condo 99LH'!C9 -> 613200 | G13: ='FH Condo'!C9 -> 1061200 | H13: - | I13: ='FH Landed (Prime)'!C9 -> 2053200
A14: Total Equity at Risk (Cash + CPF) | C14: ='HDB 1984'!C10 -> 412200 | D14: ='HDB 2005'!C10 -> 222200 | E14: ='HDB 2015'!C10 -> 412200 | F14: ='Condo 99LH'!C10 -> 763200 | G14: ='FH Condo'!C10 -> 1211200 | H14: - | I14: ='FH Landed (Prime)'!C10 -> 2203200
A15: TERMINAL VALUES (YEAR 20)
A16: Property Market Value | C16: ='HDB 1984'!F35 -> 1508236.6 | D16: ='HDB 2005'!F35 -> 1167366.8 | E16: ='HDB 2015'!F35 -> 2167333.5 | F16: ='Condo 99LH'!F35 -> 3902861.1 | G16: ='FH Condo'!F35 -> 8545380.3 | H16: - | I16: ='FH Landed (Prime)'!F35 -> 18573084
A17: Property Equity (Net of CPF) | C17: ='HDB 1984'!Q35 -> 872887.87 | D17: ='HDB 2005'!Q35 -> 728542.06 | E17: ='HDB 2015'!Q35 -> 1531984.7 | F17: ='Condo 99LH'!Q35 -> 2979508.9 | G17: ='FH Condo'!Q35 -> 7212238.5 | H17: - | I17: ='FH Landed (Prime)'!Q35 -> 16332551
A18: Liquid Portfolio | C18: ='Opportunity Cost'!C34 -> -189685.74 | D18: ='Opportunity Cost'!G34 -> 1143610 | E18: ='Opportunity Cost'!H34 -> -189685.74 | F18: ='Opportunity Cost'!D34 -> -2227400.2 | G18: ='Opportunity Cost'!E34 -> -5087120.5 | H18: ='Opportunity Cost'!F34 -> 2334206 | I18: ='Opportunity Cost'!I34 -> -11419358
A19: TOTAL NET WORTH | C19: =C18+C17 -> 683202.13 | D19: =D18+D17 -> 1872152.1 | E19: =E18+E17 -> 1342299 | F19: =F18+F17 -> 752108.73 | G19: =G18+G17 -> 2125118.1 | H19: =H18 -> 2334206 | I19: =I18+I17 -> 4913192.7
A20: PERFORMANCE METRICS
A21: NW CAGR (20yr) | C21: ='Opportunity Cost'!C42 -> -0.0078599961 | D21: ='Opportunity Cost'!G42 -> 0.043428168 | E21: ='Opportunity Cost'!H42 -> 0.026214068 | F21: ='Opportunity Cost'!D42 -> -0.0030817831 | G21: ='Opportunity Cost'!E42 -> 0.050061302 | H21: ='Opportunity Cost'!F42 -> 0.055 | I21: ='Opportunity Cost'!I42 -> 0.094998919
A22: NW vs. No Property | C22: =C19-H19 -> -1651003.9 | D22: =D19-H19 -> -462053.93 | E22: =E19-H19 -> -991906.99 | F22: =F19-H19 -> -1582097.3 | G22: =G19-H19 -> -209087.94 | H22: - | I22: =I19-H19 -> 2578986.7
A23: Annualized ROE on Equity | C23: ='HDB 1984'!I40 -> 0.048579418 | D23: ='HDB 2005'!I40 -> 0.073631354 | E23: ='HDB 2015'!I40 -> 0.074152745 | F23: ='Condo 99LH'!I40 -> 0.073812702 | G23: ='FH Condo'!I40 -> 0.094742578 | H23: - | I23: ='FH Landed (Prime)'!I40 -> 0.1059952
A24: Breakeven Year | C24: ='HDB 1984'!I41 -> 2 | D24: ='HDB 2005'!I41 -> 1 | E24: ='HDB 2015'!I41 -> 2 | F24: ='Condo 99LH'!I41 -> 2 | G24: ='FH Condo'!I41 -> 2 | H24: - | I24: ='FH Landed (Prime)'!I41 -> 1
A26: LEASE DECAY IMPACT ANALYSIS
C27: HDB 1984 | D27: HDB 2005 | E27: HDB 2015 | F27: Condo 99LH | G27: FH Condo | I27: FH Landed
A28: Starting Lease | C28: ='HDB 1984'!C15 -> 57 | D28: ='HDB 2005'!C15 -> 78 | E28: ='HDB 2015'!C15 -> 88 | F28: ='Condo 99LH'!C15 -> 93 | G28: Freehold | I28: Freehold
A29: Terminal Lease (Year 20) | C29: ='HDB 1984'!C35 -> 37 | D29: ='HDB 2005'!C35 -> 58 | E29: ='HDB 2015'!C35 -> 68 | F29: ='Condo 99LH'!C35 -> 73 | G29: Freehold | I29: Freehold
A30: Bala Factor: Start → End | C30: ='HDB 1984'!D15 -> 0.64 | D30: ='HDB 2005'!D15 -> 0.782 | E30: ='HDB 2015'!D15 -> 0.84 | F30: ='Condo 99LH'!D15 -> 0.87 | G30: 1 | I30: 1
A31: → | C31: ='HDB 1984'!D35 -> 0.464 | D31: ='HDB 2005'!D35 -> 0.648 | E31: ='HDB 2015'!D35 -> 0.72 | F31: ='Condo 99LH'!D35 -> 0.752 | G31: 1 | I31: 1
A32: Total Bala Decay (%) | C32: ='HDB 1984'!D15-'HDB 1984'!D35 -> 0.176 | D32: ='HDB 2005'!D15-'HDB 2005'!D35 -> 0.134 | E32: ='HDB 2015'!D15-'HDB 2015'!D35 -> 0.12 | F32: ='Condo 99LH'!D15-'Condo 99LH'!D35 -> 0.118 | G32: 0 | I32: 0
A33: Value Destroyed by Decay ($) | C33: ='HDB 1984'!E35*('HDB 1984'!D15-'HDB 1984'!D35) -> 572089.75 | D33: ='HDB 2005'!E35*('HDB 2005'!D15-'HDB 2005'!D35) -> 241399.93 | E33: ='HDB 2015'!E35*('HDB 2015'!D15-'HDB 2015'!D35) -> 361222.25 | F33: ='Condo 99LH'!E35*('Condo 99LH'!D15-'Condo 99LH'!D35) -> 612417.03 | G33: 0 | I33: 0
A35: 🏆 PROPERTY RANKING TABLE
A36: Rank | B36: Property | C36: Total Net Worth | D36: NW vs. No Property | E36: ROE on Equity | F36: Equity at Risk | G36: Lease Decay ($) | H36: Breakeven Yr | I36: Risk Flags | K36: Property | L36: NW | M36: ROE | N36: Equity at Risk | O36: Decay $ | P36: Breakeven | Q36: NW Rank | R36: ROE Rank | S36: Risk Flags
A37: 1 | B37: =INDEX($K$37:$K$42,MATCH(1,$Q$37:$Q$42,0)) -> FH Landed | C37: =INDEX($L$37:$L$42,MATCH(1,$Q$37:$Q$42,0)) -> 4913192.7 | D37: =INDEX($L$37:$L$42,MATCH(1,$Q$37:$Q$42,0))-$H$19 -> 2578986.7 | E37: =INDEX($M$37:$M$42,MATCH(1,$Q$37:$Q$42,0)) -> 0.1059952 | F37: =INDEX($N$37:$N$42,MATCH(1,$Q$37:$Q$42,0)) -> 2203200 | G37: =INDEX($O$37:$O$42,MATCH(1,$Q$37:$Q$42,0)) -> 0 | H37: =INDEX($P$37:$P$42,MATCH(1,$Q$37:$Q$42,0)) -> 1 | I37: =INDEX($S$37:$S$42,MATCH(1,$Q$37:$Q$42,0)) -> ⚠️ 🟢 | K37: HDB 1984 | L37: =C19 -> 683202.13 | M37: =C23 -> 0.048579418 | N37: =C14 -> 412200 | O37: =C33 -> 572089.75 | P37: =C24 -> 2 | Q37: =RANK(L37,$L$37:$L$42,0) -> 6 | R37: =RANK(M37,$M$37:$M$42,0) -> 6 | S37: =IF(L37<$H$19,"🔴 ","")&IF(O37>400000,"🟡 ","")&IF(N37>1000000,"⚠️ ","")&IF(L37>$H$19,"🟢","") -> 🔴 🟡
A38: 2 | B38: =INDEX($K$37:$K$42,MATCH(2,$Q$37:$Q$42,0)) -> FH Condo | C38: =INDEX($L$37:$L$42,MATCH(2,$Q$37:$Q$42,0)) -> 2125118.1 | D38: =INDEX($L$37:$L$42,MATCH(2,$Q$37:$Q$42,0))-$H$19 -> -209087.94 | E38: =INDEX($M$37:$M$42,MATCH(2,$Q$37:$Q$42,0)) -> 0.094742578 | F38: =INDEX($N$37:$N$42,MATCH(2,$Q$37:$Q$42,0)) -> 1211200 | G38: =INDEX($O$37:$O$42,MATCH(2,$Q$37:$Q$42,0)) -> 0 | H38: =INDEX($P$37:$P$42,MATCH(2,$Q$37:$Q$42,0)) -> 2 | I38: =INDEX($S$37:$S$42,MATCH(2,$Q$37:$Q$42,0)) -> 🔴 ⚠️ | K38: HDB 2005 | L38: =D19 -> 1872152.1 | M38: =D23 -> 0.073631354 | N38: =D14 -> 222200 | O38: =D33 -> 241399.93 | P38: =D24 -> 1 | Q38: =RANK(L38,$L$37:$L$42,0) -> 3 | R38: =RANK(M38,$M$37:$M$42,0) -> 5 | S38: =IF(L38<$H$19,"🔴 ","")&IF(O38>400000,"🟡 ","")&IF(N38>1000000,"⚠️ ","")&IF(L38>$H$19,"🟢","") -> 🔴
A39: 3 | B39: =INDEX($K$37:$K$42,MATCH(3,$Q$37:$Q$42,0)) -> HDB 2005 | C39: =INDEX($L$37:$L$42,MATCH(3,$Q$37:$Q$42,0)) -> 1872152.1 | D39: =INDEX($L$37:$L$42,MATCH(3,$Q$37:$Q$42,0))-$H$19 -> -462053.93 | E39: =INDEX($M$37:$M$42,MATCH(3,$Q$37:$Q$42,0)) -> 0.073631354 | F39: =INDEX($N$37:$N$42,MATCH(3,$Q$37:$Q$42,0)) -> 222200 | G39: =INDEX($O$37:$O$42,MATCH(3,$Q$37:$Q$42,0)) -> 241399.93 | H39: =INDEX($P$37:$P$42,MATCH(3,$Q$37:$Q$42,0)) -> 1 | I39: =INDEX($S$37:$S$42,MATCH(3,$Q$37:$Q$42,0)) -> 🔴 | K39: HDB 2015 | L39: =E19 -> 1342299 | M39: =E23 -> 0.074152745 | N39: =E14 -> 412200 | O39: =E33 -> 361222.25 | P39: =E24 -> 2 | Q39: =RANK(L39,$L$37:$L$42,0) -> 4 | R39: =RANK(M39,$M$37:$M$42,0) -> 3 | S39: =IF(L39<$H$19,"🔴 ","")&IF(O39>400000,"🟡 ","")&IF(N39>1000000,"⚠️ ","")&IF(L39>$H$19,"🟢","") -> 🔴
A40: 4 | B40: =INDEX($K$37:$K$42,MATCH(4,$Q$37:$Q$42,0)) -> HDB 2015 | C40: =INDEX($L$37:$L$42,MATCH(4,$Q$37:$Q$42,0)) -> 1342299 | D40: =INDEX($L$37:$L$42,MATCH(4,$Q$37:$Q$42,0))-$H$19 -> -991906.99 | E40: =INDEX($M$37:$M$42,MATCH(4,$Q$37:$Q$42,0)) -> 0.074152745 | F40: =INDEX($N$37:$N$42,MATCH(4,$Q$37:$Q$42,0)) -> 412200 | G40: =INDEX($O$37:$O$42,MATCH(4,$Q$37:$Q$42,0)) -> 361222.25 | H40: =INDEX($P$37:$P$42,MATCH(4,$Q$37:$Q$42,0)) -> 2 | I40: =INDEX($S$37:$S$42,MATCH(4,$Q$37:$Q$42,0)) -> 🔴 | K40: Condo 99LH | L40: =F19 -> 752108.73 | M40: =F23 -> 0.073812702 | N40: =F14 -> 763200 | O40: =F33 -> 612417.03 | P40: =F24 -> 2 | Q40: =RANK(L40,$L$37:$L$42,0) -> 5 | R40: =RANK(M40,$M$37:$M$42,0) -> 4 | S40: =IF(L40<$H$19,"🔴 ","")&IF(O40>400000,"🟡 ","")&IF(N40>1000000,"⚠️ ","")&IF(L40>$H$19,"🟢","") -> 🔴 🟡
A41: 5 | B41: =INDEX($K$37:$K$42,MATCH(5,$Q$37:$Q$42,0)) -> Condo 99LH | C41: =INDEX($L$37:$L$42,MATCH(5,$Q$37:$Q$42,0)) -> 752108.73 | D41: =INDEX($L$37:$L$42,MATCH(5,$Q$37:$Q$42,0))-$H$19 -> -1582097.3 | E41: =INDEX($M$37:$M$42,MATCH(5,$Q$37:$Q$42,0)) -> 0.073812702 | F41: =INDEX($N$37:$N$42,MATCH(5,$Q$37:$Q$42,0)) -> 763200 | G41: =INDEX($O$37:$O$42,MATCH(5,$Q$37:$Q$42,0)) -> 612417.03 | H41: =INDEX($P$37:$P$42,MATCH(5,$Q$37:$Q$42,0)) -> 2 | I41: =INDEX($S$37:$S$42,MATCH(5,$Q$37:$Q$42,0)) -> 🔴 🟡 | K41: FH Condo | L41: =G19 -> 2125118.1 | M41: =G23 -> 0.094742578 | N41: =G14 -> 1211200 | O41: =G33 -> 0 | P41: =G24 -> 2 | Q41: =RANK(L41,$L$37:$L$42,0) -> 2 | R41: =RANK(M41,$M$37:$M$42,0) -> 2 | S41: =IF(L41<$H$19,"🔴 ","")&IF(O41>400000,"🟡 ","")&IF(N41>1000000,"⚠️ ","")&IF(L41>$H$19,"🟢","") -> 🔴 ⚠️
A42: 6 | B42: =INDEX($K$37:$K$42,MATCH(6,$Q$37:$Q$42,0)) -> HDB 1984 | C42: =INDEX($L$37:$L$42,MATCH(6,$Q$37:$Q$42,0)) -> 683202.13 | D42: =INDEX($L$37:$L$42,MATCH(6,$Q$37:$Q$42,0))-$H$19 -> -1651003.9 | E42: =INDEX($M$37:$M$42,MATCH(6,$Q$37:$Q$42,0)) -> 0.048579418 | F42: =INDEX($N$37:$N$42,MATCH(6,$Q$37:$Q$42,0)) -> 412200 | G42: =INDEX($O$37:$O$42,MATCH(6,$Q$37:$Q$42,0)) -> 572089.75 | H42: =INDEX($P$37:$P$42,MATCH(6,$Q$37:$Q$42,0)) -> 2 | I42: =INDEX($S$37:$S$42,MATCH(6,$Q$37:$Q$42,0)) -> 🔴 🟡 | K42: FH Landed | L42: =I19 -> 4913192.7 | M42: =I23 -> 0.1059952 | N42: =I14 -> 2203200 | O42: =I33 -> 0 | P42: =I24 -> 1 | Q42: =RANK(L42,$L$37:$L$42,0) -> 1 | R42: =RANK(M42,$M$37:$M$42,0) -> 1 | S42: =IF(L42<$H$19,"🔴 ","")&IF(O42>400000,"🟡 ","")&IF(N42>1000000,"⚠️ ","")&IF(L42>$H$19,"🟢","") -> ⚠️ 🟢
A44: QUICK STATS | B44: Best: | C44: =B37 -> FH Landed | D44: Worst: | E44: =B42 -> HDB 1984 | F44: Spread: | G44: =C37-C42 -> 4229990.6
A45: FLAG LEGEND | B45: 🔴 Underperforms No Property | D45: 🟡 Lease decay > $400K | F45: ⚠️ Capital lock-up > $1M | H45: 🟢 Beats No Property
...

Sheet Sensitivity Analysis
A1: SENSITIVITY ANALYSIS — TWO-WAY DATA TABLES
A3: PROPERTY SELECTOR | F3: CURRENT BASE CASE VALUES | L3: HELPER CALCS (selected property)
A4: Select Property: | C4: FH Condo | F4: Land Appreciation: | H4: {=INDEX(Assumptions!C34:H34,C5)} -> 0.04 | L4: Loan Amount | N4: =C6*Assumptions!C22 -> 2925000
A5: Property #: | C5: =MATCH(C4,{"HDB 1984","Condo 99LH","FH Condo","HDB 2005","HDB 2015","FH Landed (Prime)"},0) -> 3 | F5: Mortgage Rate: | H5: {=INDEX('Scenario Tables'!C27:H27,C5)} -> 0.01671 | L5: Bala Start | N5: {=INDEX(Assumptions!C33:H33,C5)} -> Freehold
A6: Purchase Price: | C6: {=INDEX(Assumptions!C31:H31,C5)} -> 3900000 | F6: Portfolio CAGR: | H6: =Assumptions!C54 -> 0.055 | L6: Bala End Factor | N6: =IF(OR(N5="Freehold",N5>=900),1,INDEX('Bala Table'!B:B,MATCH(N5-20,'Bala Table'!A:A,-1))) -> 1
L7: Bala Start Factor | N7: =IF(OR(N5="Freehold",N5>=900),1,INDEX('Bala Table'!B:B,MATCH(N5,'Bala Table'!A:A,-1))) -> 1
L8: Tenure | N8: =Assumptions!C26 -> 30
A9: TABLE 1: TERMINAL PROPERTY EQUITY ($) — Land Appreciation vs. Mortgage Rate | L9: CPF Accrued Int (Y20) | N9: =Assumptions!C8*((1+Assumptions!C9)^20-1)+Assumptions!C8*((1+Assumptions!C9)^20-1) -> 191584.93
A10: Land Appr. ↓ Mort. Rate → | C10: Table 1: Terminal Property Equity (Net of Loan & CPF) | D10: Mortgage Rate | L10: Total Equity at Risk | N10: {=C6*Assumptions!C24+INDEX(Assumptions!C49:H49,C5)+Assumptions!C8} -> 969000
C11: Land Appr. | D11: 0.015 | E11: 0.02 | F11: 0.025 | G11: 0.03 | H11: 0.035 | I11: 0.04 | J11: 0.05 | L11: Cumul. Net Rental CF (Y20) | N11: =CHOOSE(C5,'HDB 1984'!N35,'Condo 99LH'!N35,'FH Condo'!N35,'HDB 2005'!N35,'HDB 2015'!N35,'FH Landed (Prime)'!N35) -> 1227977.7
C12: -0.01 | D12: =(($C$6/$N$7)*(1+$C12)^20*$N$6)-(PV(D$11/12,($N$8-20)*12,-PMT(D$11/12,$N$8*12,-$N$4)))-$N$9 -> 1874006.9 | E12: =(($C$6/$N$7)*(1+$C12)^20*$N$6)-(PV(E$11/12,($N$8-20)*12,-PMT(E$11/12,$N$8*12,-$N$4)))-$N$9 -> 1823275.1 | F12: =(($C$6/$N$7)*(1+$C12)^20*$N$6)-(PV(F$11/12,($N$8-20)*12,-PMT(F$11/12,$N$8*12,-$N$4)))-$N$9 -> 1772273.7 | G12: =(($C$6/$N$7)*(1+$C12)^20*$N$6)-(PV(G$11/12,($N$8-20)*12,-PMT(G$11/12,$N$8*12,-$N$4)))-$N$9 -> 1721137.1 | H12: =(($C$6/$N$7)*(1+$C12)^20*$N$6)-(PV(H$11/12,($N$8-20)*12,-PMT(H$11/12,$N$8*12,-$N$4)))-$N$9 -> 1669997.9 | I12: =(($C$6/$N$7)*(1+$C12)^20*$N$6)-(PV(I$11/12,($N$8-20)*12,-PMT(I$11/12,$N$8*12,-$N$4)))-$N$9 -> 1618986.2 | J12: =(($C$6/$N$7)*(1+$C12)^20*$N$6)-(PV(J$11/12,($N$8-20)*12,-PMT(J$11/12,$N$8*12,-$N$4)))-$N$9 -> 1517843.3 | N12: HDB 1984
C13: 0 | D13: =(($C$6/$N$7)*(1+$C13)^20*$N$6)-(PV(D$11/12,($N$8-20)*12,-PMT(D$11/12,$N$8*12,-$N$4)))-$N$9 -> 2584169.9 | E13: =(($C$6/$N$7)*(1+$C13)^20*$N$6)-(PV(E$11/12,($N$8-20)*12,-PMT(E$11/12,$N$8*12,-$N$4)))-$N$9 -> 2533438 | F13: =(($C$6/$N$7)*(1+$C13)^20*$N$6)-(PV(F$11/12,($N$8-20)*12,-PMT(F$11/12,$N$8*12,-$N$4)))-$N$9 -> 2482436.7 | G13: =(($C$6/$N$7)*(1+$C13)^20*$N$6)-(PV(G$11/12,($N$8-20)*12,-PMT(G$11/12,$N$8*12,-$N$4)))-$N$9 -> 2431300 | H13: =(($C$6/$N$7)*(1+$C13)^20*$N$6)-(PV(H$11/12,($N$8-20)*12,-PMT(H$11/12,$N$8*12,-$N$4)))-$N$9 -> 2380160.8 | I13: =(($C$6/$N$7)*(1+$C13)^20*$N$6)-(PV(I$11/12,($N$8-20)*12,-PMT(I$11/12,$N$8*12,-$N$4)))-$N$9 -> 2329149.1 | J13: =(($C$6/$N$7)*(1+$C13)^20*$N$6)-(PV(J$11/12,($N$8-20)*12,-PMT(J$11/12,$N$8*12,-$N$4)))-$N$9 -> 2228006.2 | N13: Condo 99LH
C14: 0.02 | D14: =(($C$6/$N$7)*(1+$C14)^20*$N$6)-(PV(D$11/12,($N$8-20)*12,-PMT(D$11/12,$N$8*12,-$N$4)))-$N$9 -> 4479364.7 | E14: =(($C$6/$N$7)*(1+$C14)^20*$N$6)-(PV(E$11/12,($N$8-20)*12,-PMT(E$11/12,$N$8*12,-$N$4)))-$N$9 -> 4428632.9 | F14: =(($C$6/$N$7)*(1+$C14)^20*$N$6)-(PV(F$11/12,($N$8-20)*12,-PMT(F$11/12,$N$8*12,-$N$4)))-$N$9 -> 4377631.5 | G14: =(($C$6/$N$7)*(1+$C14)^20*$N$6)-(PV(G$11/12,($N$8-20)*12,-PMT(G$11/12,$N$8*12,-$N$4)))-$N$9 -> 4326494.9 | H14: =(($C$6/$N$7)*(1+$C14)^20*$N$6)-(PV(H$11/12,($N$8-20)*12,-PMT(H$11/12,$N$8*12,-$N$4)))-$N$9 -> 4275355.7 | I14: =(($C$6/$N$7)*(1+$C14)^20*$N$6)-(PV(I$11/12,($N$8-20)*12,-PMT(I$11/12,$N$8*12,-$N$4)))-$N$9 -> 4224343.9 | J14: =(($C$6/$N$7)*(1+$C14)^20*$N$6)-(PV(J$11/12,($N$8-20)*12,-PMT(J$11/12,$N$8*12,-$N$4)))-$N$9 -> 4123201.1 | N14: FH Condo
C15: 0.03 | D15: =(($C$6/$N$7)*(1+$C15)^20*$N$6)-(PV(D$11/12,($N$8-20)*12,-PMT(D$11/12,$N$8*12,-$N$4)))-$N$9 -> 5728003.7 | E15: =(($C$6/$N$7)*(1+$C15)^20*$N$6)-(PV(E$11/12,($N$8-20)*12,-PMT(E$11/12,$N$8*12,-$N$4)))-$N$9 -> 5677271.8 | F15: =(($C$6/$N$7)*(1+$C15)^20*$N$6)-(PV(F$11/12,($N$8-20)*12,-PMT(F$11/12,$N$8*12,-$N$4)))-$N$9 -> 5626270.5 | G15: =(($C$6/$N$7)*(1+$C15)^20*$N$6)-(PV(G$11/12,($N$8-20)*12,-PMT(G$11/12,$N$8*12,-$N$4)))-$N$9 -> 5575133.8 | H15: =(($C$6/$N$7)*(1+$C15)^20*$N$6)-(PV(H$11/12,($N$8-20)*12,-PMT(H$11/12,$N$8*12,-$N$4)))-$N$9 -> 5523994.7 | I15: =(($C$6/$N$7)*(1+$C15)^20*$N$6)-(PV(I$11/12,($N$8-20)*12,-PMT(I$11/12,$N$8*12,-$N$4)))-$N$9 -> 5472982.9 | J15: =(($C$6/$N$7)*(1+$C15)^20*$N$6)-(PV(J$11/12,($N$8-20)*12,-PMT(J$11/12,$N$8*12,-$N$4)))-$N$9 -> 5371840.1 | N15: HDB 2005
C16: 0.05 | D16: =(($C$6/$N$7)*(1+$C16)^20*$N$6)-(PV(D$11/12,($N$8-20)*12,-PMT(D$11/12,$N$8*12,-$N$4)))-$N$9 -> 9032030.9 | E16: =(($C$6/$N$7)*(1+$C16)^20*$N$6)-(PV(E$11/12,($N$8-20)*12,-PMT(E$11/12,$N$8*12,-$N$4)))-$N$9 -> 8981299.1 | F16: =(($C$6/$N$7)*(1+$C16)^20*$N$6)-(PV(F$11/12,($N$8-20)*12,-PMT(F$11/12,$N$8*12,-$N$4)))-$N$9 -> 8930297.7 | G16: =(($C$6/$N$7)*(1+$C16)^20*$N$6)-(PV(G$11/12,($N$8-20)*12,-PMT(G$11/12,$N$8*12,-$N$4)))-$N$9 -> 8879161.1 | H16: =(($C$6/$N$7)*(1+$C16)^20*$N$6)-(PV(H$11/12,($N$8-20)*12,-PMT(H$11/12,$N$8*12,-$N$4)))-$N$9 -> 8828021.9 | I16: =(($C$6/$N$7)*(1+$C16)^20*$N$6)-(PV(I$11/12,($N$8-20)*12,-PMT(I$11/12,$N$8*12,-$N$4)))-$N$9 -> 8777010.1 | J16: =(($C$6/$N$7)*(1+$C16)^20*$N$6)-(PV(J$11/12,($N$8-20)*12,-PMT(J$11/12,$N$8*12,-$N$4)))-$N$9 -> 8675867.3 | N16: HDB 2015
C17: 0.07 | D17: =(($C$6/$N$7)*(1+$C17)^20*$N$6)-(PV(D$11/12,($N$8-20)*12,-PMT(D$11/12,$N$8*12,-$N$4)))-$N$9 -> 13775939 | E17: =(($C$6/$N$7)*(1+$C17)^20*$N$6)-(PV(E$11/12,($N$8-20)*12,-PMT(E$11/12,$N$8*12,-$N$4)))-$N$9 -> 13725207 | F17: =(($C$6/$N$7)*(1+$C17)^20*$N$6)-(PV(F$11/12,($N$8-20)*12,-PMT(F$11/12,$N$8*12,-$N$4)))-$N$9 -> 13674206 | G17: =(($C$6/$N$7)*(1+$C17)^20*$N$6)-(PV(G$11/12,($N$8-20)*12,-PMT(G$11/12,$N$8*12,-$N$4)))-$N$9 -> 13623069 | H17: =(($C$6/$N$7)*(1+$C17)^20*$N$6)-(PV(H$11/12,($N$8-20)*12,-PMT(H$11/12,$N$8*12,-$N$4)))-$N$9 -> 13571930 | I17: =(($C$6/$N$7)*(1+$C17)^20*$N$6)-(PV(I$11/12,($N$8-20)*12,-PMT(I$11/12,$N$8*12,-$N$4)))-$N$9 -> 13520918 | J17: =(($C$6/$N$7)*(1+$C17)^20*$N$6)-(PV(J$11/12,($N$8-20)*12,-PMT(J$11/12,$N$8*12,-$N$4)))-$N$9 -> 13419776 | N17: FH Landed (Prime)
C18: 0.1 | D18: =(($C$6/$N$7)*(1+$C18)^20*$N$6)-(PV(D$11/12,($N$8-20)*12,-PMT(D$11/12,$N$8*12,-$N$4)))-$N$9 -> 24921420 | E18: =(($C$6/$N$7)*(1+$C18)^20*$N$6)-(PV(E$11/12,($N$8-20)*12,-PMT(E$11/12,$N$8*12,-$N$4)))-$N$9 -> 24870688 | F18: =(($C$6/$N$7)*(1+$C18)^20*$N$6)-(PV(F$11/12,($N$8-20)*12,-PMT(F$11/12,$N$8*12,-$N$4)))-$N$9 -> 24819686 | G18: =(($C$6/$N$7)*(1+$C18)^20*$N$6)-(PV(G$11/12,($N$8-20)*12,-PMT(G$11/12,$N$8*12,-$N$4)))-$N$9 -> 24768550 | H18: =(($C$6/$N$7)*(1+$C18)^20*$N$6)-(PV(H$11/12,($N$8-20)*12,-PMT(H$11/12,$N$8*12,-$N$4)))-$N$9 -> 24717411 | I18: =(($C$6/$N$7)*(1+$C18)^20*$N$6)-(PV(I$11/12,($N$8-20)*12,-PMT(I$11/12,$N$8*12,-$N$4)))-$N$9 -> 24666399 | J18: =(($C$6/$N$7)*(1+$C18)^20*$N$6)-(PV(J$11/12,($N$8-20)*12,-PMT(J$11/12,$N$8*12,-$N$4)))-$N$9 -> 24565256
C20: Table 2: Total Net Worth at Year 20 (Property Equity + Net Rental Cash Flow)
C21: Land Appr. ↓ Mortgage → | D21: 0.015 | E21: 0.02 | F21: 0.025 | G21: 0.03 | H21: 0.035 | I21: 0.04 | J21: 0.05
C22: -0.01 | D22: =D12+$N$11 -> 3101984.6 | E22: =E12+$N$11 -> 3051252.7 | F22: =F12+$N$11 -> 3000251.4 | G22: =G12+$N$11 -> 2949114.7 | H22: =H12+$N$11 -> 2897975.6 | I22: =I12+$N$11 -> 2846963.8 | J22: =J12+$N$11 -> 2745821
C23: 0 | D23: =D13+$N$11 -> 3812147.5 | E23: =E13+$N$11 -> 3761415.7 | F23: =F13+$N$11 -> 3710414.3 | G23: =G13+$N$11 -> 3659277.7 | H23: =H13+$N$11 -> 3608138.5 | I23: =I13+$N$11 -> 3557126.8 | J23: =J13+$N$11 -> 3455983.9
C24: 0.02 | D24: =D14+$N$11 -> 5707342.4 | E24: =E14+$N$11 -> 5656610.5 | F24: =F14+$N$11 -> 5605609.2 | G24: =G14+$N$11 -> 5554472.5 | H24: =H14+$N$11 -> 5503333.4 | I24: =I14+$N$11 -> 5452321.6 | J24: =J14+$N$11 -> 5351178.8
C25: 0.03 | D25: =D15+$N$11 -> 6955981.4 | E25: =E15+$N$11 -> 6905249.5 | F25: =F15+$N$11 -> 6854248.1 | G25: =G15+$N$11 -> 6803111.5 | H25: =H15+$N$11 -> 6751972.3 | I25: =I15+$N$11 -> 6700960.6 | J25: =J15+$N$11 -> 6599817.7
C26: 0.05 | D26: =D16+$N$11 -> 10260009 | E26: =E16+$N$11 -> 10209277 | F26: =F16+$N$11 -> 10158275 | G26: =G16+$N$11 -> 10107139 | H26: =H16+$N$11 -> 10056000 | I26: =I16+$N$11 -> 10004988 | J26: =J16+$N$11 -> 9903845
C27: 0.07 | D27: =D17+$N$11 -> 15003917 | E27: =E17+$N$11 -> 14953185 | F27: =F17+$N$11 -> 14902184 | G27: =G17+$N$11 -> 14851047 | H27: =H17+$N$11 -> 14799908 | I27: =I17+$N$11 -> 14748896 | J27: =J17+$N$11 -> 14647753
C28: 0.1 | D28: =D18+$N$11 -> 26149397 | E28: =E18+$N$11 -> 26098665 | F28: =F18+$N$11 -> 26047664 | G28: =G18+$N$11 -> 25996527 | H28: =H18+$N$11 -> 25945388 | I28: =I18+$N$11 -> 25894377 | J28: =J18+$N$11 -> 25793234
C30: Table 3: Property Advantage vs. Liquid Portfolio ($)
C31: Land Appr. ↓ Alt. CAGR → | D31: 0.03 | E31: 0.04 | F31: 0.05 | G31: 0.06 | H31: 0.07 | I31: 0.08 | J31: 0.1
C32: -0.01 | D32: =(($C$6/$N$7)*(1+$C32)^20*$N$6)-(PV($H$5/12,($N$8-20)*12,-PMT($H$5/12,$N$8*12,-$N$4)))-$N$9+$N$11-$N$10*(1+D$31)^20 -> 1334551.2 | E32: =(($C$6/$N$7)*(1+$C32)^20*$N$6)-(PV($H$5/12,($N$8-20)*12,-PMT($H$5/12,$N$8*12,-$N$4)))-$N$9+$N$11-$N$10*(1+E$31)^20 -> 961474.67 | F32: =(($C$6/$N$7)*(1+$C32)^20*$N$6)-(PV($H$5/12,($N$8-20)*12,-PMT($H$5/12,$N$8*12,-$N$4)))-$N$9+$N$11-$N$10*(1+F$31)^20 -> 513627.51 | G32: =(($C$6/$N$7)*(1+$C32)^20*$N$6)-(PV($H$5/12,($N$8-20)*12,-PMT($H$5/12,$N$8*12,-$N$4)))-$N$9+$N$11-$N$10*(1+G$31)^20 -> -23041.281 | H32: =(($C$6/$N$7)*(1+$C32)^20*$N$6)-(PV($H$5/12,($N$8-20)*12,-PMT($H$5/12,$N$8*12,-$N$4)))-$N$9+$N$11-$N$10*(1+H$31)^20 -> -665051.25 | I32: =(($C$6/$N$7)*(1+$C32)^20*$N$6)-(PV($H$5/12,($N$8-20)*12,-PMT($H$5/12,$N$8*12,-$N$4)))-$N$9+$N$11-$N$10*(1+I$31)^20 -> -1431794.5 | J32: =(($C$6/$N$7)*(1+$C32)^20*$N$6)-(PV($H$5/12,($N$8-20)*12,-PMT($H$5/12,$N$8*12,-$N$4)))-$N$9+$N$11-$N$10*(1+J$31)^20 -> -3434274.5
C33: 0 | D33: =(($C$6/$N$7)*(1+$C33)^20*$N$6)-(PV($H$5/12,($N$8-20)*12,-PMT($H$5/12,$N$8*12,-$N$4)))-$N$9+$N$11-$N$10*(1+D$31)^20 -> 2044714.1 | E33: =(($C$6/$N$7)*(1+$C33)^20*$N$6)-(PV($H$5/12,($N$8-20)*12,-PMT($H$5/12,$N$8*12,-$N$4)))-$N$9+$N$11-$N$10*(1+E$31)^20 -> 1671637.6 | F33: =(($C$6/$N$7)*(1+$C33)^20*$N$6)-(PV($H$5/12,($N$8-20)*12,-PMT($H$5/12,$N$8*12,-$N$4)))-$N$9+$N$11-$N$10*(1+F$31)^20 -> 1223790.5 | G33: =(($C$6/$N$7)*(1+$C33)^20*$N$6)-(PV($H$5/12,($N$8-20)*12,-PMT($H$5/12,$N$8*12,-$N$4)))-$N$9+$N$11-$N$10*(1+G$31)^20 -> 687121.66 | H33: =(($C$6/$N$7)*(1+$C33)^20*$N$6)-(PV($H$5/12,($N$8-20)*12,-PMT($H$5/12,$N$8*12,-$N$4)))-$N$9+$N$11-$N$10*(1+H$31)^20 -> 45111.69 | I33: =(($C$6/$N$7)*(1+$C33)^20*$N$6)-(PV($H$5/12,($N$8-20)*12,-PMT($H$5/12,$N$8*12,-$N$4)))-$N$9+$N$11-$N$10*(1+I$31)^20 -> -721631.54 | J33: =(($C$6/$N$7)*(1+$C33)^20*$N$6)-(PV($H$5/12,($N$8-20)*12,-PMT($H$5/12,$N$8*12,-$N$4)))-$N$9+$N$11-$N$10*(1+J$31)^20 -> -2724111.5
C34: 0.02 | D34: =(($C$6/$N$7)*(1+$C34)^20*$N$6)-(PV($H$5/12,($N$8-20)*12,-PMT($H$5/12,$N$8*12,-$N$4)))-$N$9+$N$11-$N$10*(1+D$31)^20 -> 3939909 | E34: =(($C$6/$N$7)*(1+$C34)^20*$N$6)-(PV($H$5/12,($N$8-20)*12,-PMT($H$5/12,$N$8*12,-$N$4)))-$N$9+$N$11-$N$10*(1+E$31)^20 -> 3566832.5 | F34: =(($C$6/$N$7)*(1+$C34)^20*$N$6)-(PV($H$5/12,($N$8-20)*12,-PMT($H$5/12,$N$8*12,-$N$4)))-$N$9+$N$11-$N$10*(1+F$31)^20 -> 3118985.3 | G34: =(($C$6/$N$7)*(1+$C34)^20*$N$6)-(PV($H$5/12,($N$8-20)*12,-PMT($H$5/12,$N$8*12,-$N$4)))-$N$9+$N$11-$N$10*(1+G$31)^20 -> 2582316.5 | H34: =(($C$6/$N$7)*(1+$C34)^20*$N$6)-(PV($H$5/12,($N$8-20)*12,-PMT($H$5/12,$N$8*12,-$N$4)))-$N$9+$N$11-$N$10*(1+H$31)^20 -> 1940306.5 | I34: =(($C$6/$N$7)*(1+$C34)^20*$N$6)-(PV($H$5/12,($N$8-20)*12,-PMT($H$5/12,$N$8*12,-$N$4)))-$N$9+$N$11-$N$10*(1+I$31)^20 -> 1173563.3 | J34: =(($C$6/$N$7)*(1+$C34)^20*$N$6)-(PV($H$5/12,($N$8-20)*12,-PMT($H$5/12,$N$8*12,-$N$4)))-$N$9+$N$11-$N$10*(1+J$31)^20 -> -828916.67
C35: 0.03 | D35: =(($C$6/$N$7)*(1+$C35)^20*$N$6)-(PV($H$5/12,($N$8-20)*12,-PMT($H$5/12,$N$8*12,-$N$4)))-$N$9+$N$11-$N$10*(1+D$31)^20 -> 5188548 | E35: =(($C$6/$N$7)*(1+$C35)^20*$N$6)-(PV($H$5/12,($N$8-20)*12,-PMT($H$5/12,$N$8*12,-$N$4)))-$N$9+$N$11-$N$10*(1+E$31)^20 -> 4815471.4 | F35: =(($C$6/$N$7)*(1+$C35)^20*$N$6)-(PV($H$5/12,($N$8-20)*12,-PMT($H$5/12,$N$8*12,-$N$4)))-$N$9+$N$11-$N$10*(1+F$31)^20 -> 4367624.3 | G35: =(($C$6/$N$7)*(1+$C35)^20*$N$6)-(PV($H$5/12,($N$8-20)*12,-PMT($H$5/12,$N$8*12,-$N$4)))-$N$9+$N$11-$N$10*(1+G$31)^20 -> 3830955.5 | H35: =(($C$6/$N$7)*(1+$C35)^20*$N$6)-(PV($H$5/12,($N$8-20)*12,-PMT($H$5/12,$N$8*12,-$N$4)))-$N$9+$N$11-$N$10*(1+H$31)^20 -> 3188945.5 | I35: =(($C$6/$N$7)*(1+$C35)^20*$N$6)-(PV($H$5/12,($N$8-20)*12,-PMT($H$5/12,$N$8*12,-$N$4)))-$N$9+$N$11-$N$10*(1+I$31)^20 -> 2422202.3 | J35: =(($C$6/$N$7)*(1+$C35)^20*$N$6)-(PV($H$5/12,($N$8-20)*12,-PMT($H$5/12,$N$8*12,-$N$4)))-$N$9+$N$11-$N$10*(1+J$31)^20 -> 419722.3
C36: 0.05 | D36: =(($C$6/$N$7)*(1+$C36)^20*$N$6)-(PV($H$5/12,($N$8-20)*12,-PMT($H$5/12,$N$8*12,-$N$4)))-$N$9+$N$11-$N$10*(1+D$31)^20 -> 8492575.2 | E36: =(($C$6/$N$7)*(1+$C36)^20*$N$6)-(PV($H$5/12,($N$8-20)*12,-PMT($H$5/12,$N$8*12,-$N$4)))-$N$9+$N$11-$N$10*(1+E$31)^20 -> 8119498.7 | F36: =(($C$6/$N$7)*(1+$C36)^20*$N$6)-(PV($H$5/12,($N$8-20)*12,-PMT($H$5/12,$N$8*12,-$N$4)))-$N$9+$N$11-$N$10*(1+F$31)^20 -> 7671651.5 | G36: =(($C$6/$N$7)*(1+$C36)^20*$N$6)-(PV($H$5/12,($N$8-20)*12,-PMT($H$5/12,$N$8*12,-$N$4)))-$N$9+$N$11-$N$10*(1+G$31)^20 -> 7134982.7 | H36: =(($C$6/$N$7)*(1+$C36)^20*$N$6)-(PV($H$5/12,($N$8-20)*12,-PMT($H$5/12,$N$8*12,-$N$4)))-$N$9+$N$11-$N$10*(1+H$31)^20 -> 6492972.7 | I36: =(($C$6/$N$7)*(1+$C36)^20*$N$6)-(PV($H$5/12,($N$8-20)*12,-PMT($H$5/12,$N$8*12,-$N$4)))-$N$9+$N$11-$N$10*(1+I$31)^20 -> 5726229.5 | J36: =(($C$6/$N$7)*(1+$C36)^20*$N$6)-(PV($H$5/12,($N$8-20)*12,-PMT($H$5/12,$N$8*12,-$N$4)))-$N$9+$N$11-$N$10*(1+J$31)^20 -> 3723749.5
C37: 0.07 | D37: =(($C$6/$N$7)*(1+$C37)^20*$N$6)-(PV($H$5/12,($N$8-20)*12,-PMT($H$5/12,$N$8*12,-$N$4)))-$N$9+$N$11-$N$10*(1+D$31)^20 -> 13236484 | E37: =(($C$6/$N$7)*(1+$C37)^20*$N$6)-(PV($H$5/12,($N$8-20)*12,-PMT($H$5/12,$N$8*12,-$N$4)))-$N$9+$N$11-$N$10*(1+E$31)^20 -> 12863407 | F37: =(($C$6/$N$7)*(1+$C37)^20*$N$6)-(PV($H$5/12,($N$8-20)*12,-PMT($H$5/12,$N$8*12,-$N$4)))-$N$9+$N$11-$N$10*(1+F$31)^20 -> 12415560 | G37: =(($C$6/$N$7)*(1+$C37)^20*$N$6)-(PV($H$5/12,($N$8-20)*12,-PMT($H$5/12,$N$8*12,-$N$4)))-$N$9+$N$11-$N$10*(1+G$31)^20 -> 11878891 | H37: =(($C$6/$N$7)*(1+$C37)^20*$N$6)-(PV($H$5/12,($N$8-20)*12,-PMT($H$5/12,$N$8*12,-$N$4)))-$N$9+$N$11-$N$10*(1+H$31)^20 -> 11236881 | I37: =(($C$6/$N$7)*(1+$C37)^20*$N$6)-(PV($H$5/12,($N$8-20)*12,-PMT($H$5/12,$N$8*12,-$N$4)))-$N$9+$N$11-$N$10*(1+I$31)^20 -> 10470138 | J37: =(($C$6/$N$7)*(1+$C37)^20*$N$6)-(PV($H$5/12,($N$8-20)*12,-PMT($H$5/12,$N$8*12,-$N$4)))-$N$9+$N$11-$N$10*(1+J$31)^20 -> 8467657.9
C38: 0.1 | D38: =(($C$6/$N$7)*(1+$C38)^20*$N$6)-(PV($H$5/12,($N$8-20)*12,-PMT($H$5/12,$N$8*12,-$N$4)))-$N$9+$N$11-$N$10*(1+D$31)^20 -> 24381964 | E38: =(($C$6/$N$7)*(1+$C38)^20*$N$6)-(PV($H$5/12,($N$8-20)*12,-PMT($H$5/12,$N$8*12,-$N$4)))-$N$9+$N$11-$N$10*(1+E$31)^20 -> 24008887 | F38: =(($C$6/$N$7)*(1+$C38)^20*$N$6)-(PV($H$5/12,($N$8-20)*12,-PMT($H$5/12,$N$8*12,-$N$4)))-$N$9+$N$11-$N$10*(1+F$31)^20 -> 23561040 | G38: =(($C$6/$N$7)*(1+$C38)^20*$N$6)-(PV($H$5/12,($N$8-20)*12,-PMT($H$5/12,$N$8*12,-$N$4)))-$N$9+$N$11-$N$10*(1+G$31)^20 -> 23024371 | H38: =(($C$6/$N$7)*(1+$C38)^20*$N$6)-(PV($H$5/12,($N$8-20)*12,-PMT($H$5/12,$N$8*12,-$N$4)))-$N$9+$N$11-$N$10*(1+H$31)^20 -> 22382361 | I38: =(($C$6/$N$7)*(1+$C38)^20*$N$6)-(PV($H$5/12,($N$8-20)*12,-PMT($H$5/12,$N$8*12,-$N$4)))-$N$9+$N$11-$N$10*(1+I$31)^20 -> 21615618 | J38: =(($C$6/$N$7)*(1+$C38)^20*$N$6)-(PV($H$5/12,($N$8-20)*12,-PMT($H$5/12,$N$8*12,-$N$4)))-$N$9+$N$11-$N$10*(1+J$31)^20 -> 19613138

Sheet Scenario Tables
A1: SCENARIO TABLES — Edit values below to customize each dropdown option
A3: 1. LAND APPRECIATION RATES (% p.a.)
A4: Scenario | B4: Active? | C4: HDB 1984 | D4: Condo 99LH | E4: FH Condo | F4: HDB 2005 | G4: HDB 2015 | H4: FH Landed (Prime)
A5: Pessimistic | B5: =IF(Assumptions!B34="Pessimistic","✔","") | C5: 0.01 | D5: 0.01 | E5: 0.01 | F5: 0.01 | G5: 0.01 | H5: 0.01
A6: Base | B6: =IF(Assumptions!B34="Base","✔","") | C6: 0.025 | D6: 0.025 | E6: 0.025 | F6: 0.025 | G6: 0.025 | H6: 0.025
A7: Optimistic | B7: =IF(Assumptions!B34="Optimistic","✔","") | C7: 0.04 | D7: 0.04 | E7: 0.04 | F7: 0.04 | G7: 0.04 | H7: 0.04
A8: Custom | B8: =IF(Assumptions!B34="Custom","✔","") -> ✔ | C8: 0.02 | D8: 0.03 | E8: 0.04 | F8: 0.03 | G8: 0.03 | H8: 0.05
A10: 2. MORTGAGE RATE SCENARIOS
A11: Scenario | B11: Active? | C11: Mortgage Rate | D11: Description
A12: Base | B12: =IF(Assumptions!C18="Base","✔","") -> ✔ | C12: =Assumptions!C15 -> 0.01671 | D12: SORA + Bank Spread (auto-calculated)
A13: Stress | B13: =IF(Assumptions!C18="Stress","✔","") | C13: =Assumptions!C16 -> 0.035 | D13: Edit in Assumptions!C16
A14: Severe | B14: =IF(Assumptions!C18="Severe","✔","") | C14: =Assumptions!C17 -> 0.05 | D14: Edit in Assumptions!C17
A16: 3. ABSD RATES BY RESIDENCY STATUS
A17: Residency Status | B17: Active? | C17: ABSD Rate | D17: Description
A18: SC 1st Property | B18: =IF(Assumptions!C10="SC 1st Property","✔","") -> ✔ | C18: 0 | D18: Singapore Citizen, 1st property
A19: SC 2nd Property | B19: =IF(Assumptions!C10="SC 2nd Property","✔","") | C19: 0.2 | D19: Singapore Citizen, 2nd property
A20: PR | B20: =IF(Assumptions!C10="PR","✔","") | C20: 0.05 | D20: Permanent Resident
A22: 4. MORTGAGE RATES BY PROPERTY
A23: Scenario | B23: Active? | C23: HDB 1984 | D23: Condo 99LH | E23: FH Condo | F23: HDB 2005 | G23: HDB 2015 | H23: FH Landed (Prime)
A24: Base | B24: =IF(Assumptions!C18="Base","✔","") -> ✔ | C24: 0.026 | D24: =Assumptions!C15 -> 0.01671 | E24: =Assumptions!C15 -> 0.01671 | F24: 0.026 | G24: 0.026 | H24: =Assumptions!C15 -> 0.01671
A25: Stress | B25: =IF(Assumptions!C18="Stress","✔","") | C25: 0.026 | D25: =Assumptions!C16 -> 0.035 | E25: =Assumptions!C16 -> 0.035 | F25: 0.026 | G25: 0.026 | H25: =Assumptions!C16 -> 0.035
A26: Severe | B26: =IF(Assumptions!C18="Severe","✔","") | C26: 0.026 | D26: =Assumptions!C17 -> 0.05 | E26: =Assumptions!C17 -> 0.05 | F26: 0.026 | G26: 0.026 | H26: =Assumptions!C17 -> 0.05
A27: → Active Rate | C27: =INDEX(C24:C26,MATCH(Assumptions!C18,A24:A26,0)) -> 0.026 | D27: =INDEX(D24:D26,MATCH(Assumptions!C18,A24:A26,0)) -> 0.01671 | E27: =INDEX(E24:E26,MATCH(Assumptions!C18,A24:A26,0)) -> 0.01671 | F27: =INDEX(F24:F26,MATCH(Assumptions!C18,A24:A26,0)) -> 0.026 | G27: =INDEX(G24:G26,MATCH(Assumptions!C18,A24:A26,0)) -> 0.026 | H27: =INDEX(H24:H26,MATCH(Assumptions!C18,A24:A26,0)) -> 0.01671
A33: HOW TO USE
A34: ① Edit blue values in the tables above to change what each scenario means.
A35: ② Switch scenarios using the dropdowns in the Assumptions sheet (B34, C18, C10).
A36: ③ The ✔ column shows which scenario is currently active — the model auto-reads from this table.
A37: ④ Land appreciation: each property can have its own rate per scenario (edit C5:H7 independently).
A38: ⑤ "Custom" row in Table 1 links to Assumptions!I34 — type your rate there or edit I34 directly.

Sheet Opportunity Cost
A1: OPPORTUNITY COST ANALYSIS — LIQUID CAPITAL DEPLOYMENT
A3: CAPITAL DEPLOYMENT SUMMARY
C4: HDB 1984 | D4: Condo 99LH | E4: FH Condo | G4: HDB 2005 | H4: HDB 2015 | I4: FH Landed (Prime)
A5: Total Net Worth | C5: =Assumptions!C7 -> 800000 | D5: =Assumptions!C7 -> 800000 | E5: =Assumptions!C7 -> 800000 | G5: =Assumptions!C7 -> 800000 | H5: =Assumptions!C7 -> 800000 | I5: =Assumptions!C7 -> 800000
A6: Cash Deployed in Property (Day 1) | C6: ='HDB 1984'!C9 -> 262200 | D6: ='Condo 99LH'!C9 -> 613200 | E6: ='FH Condo'!C9 -> 1061200 | G6: ='HDB 2005'!C9 -> 72200 | H6: ='HDB 2015'!C9 -> 262200 | I6: ='FH Landed (Prime)'!C9 -> 2053200
A7: CPF OA Deployed | C7: ='HDB 1984'!C7 -> 150000 | D7: ='Condo 99LH'!C7 -> 150000 | E7: ='FH Condo'!C7 -> 150000 | G7: ='HDB 2005'!C7 -> 150000 | H7: ='HDB 2015'!C7 -> 150000 | I7: ='FH Landed (Prime)'!C7 -> 150000
A8: Remaining Liquid Capital | C8: =C5-C6 -> 537800 | D8: =D5-D6 -> 186800 | E8: =E5-E6 -> -261200 | G8: =G5-G6 -> 727800 | H8: =H5-H6 -> 537800 | I8: =I5-I6 -> -1253200
A9: Benchmark Return (CAGR) | C9: =Assumptions!C54 -> 0.055 | D9: =Assumptions!C54 -> 0.055 | E9: =Assumptions!C54 -> 0.055 | G9: =Assumptions!C54 -> 0.055 | H9: =Assumptions!C54 -> 0.055 | I9: =Assumptions!C54 -> 0.055
A10: Annual Mortgage Cash Outflow | C10: ='HDB 1984'!C12 -> 50442.804 | D10: ='Condo 99LH'!C12 -> 79511.645 | E10: ='FH Condo'!C12 -> 124038.17 | G10: ='HDB 2005'!C12 -> 28103.848 | H10: ='HDB 2015'!C12 -> 50442.804 | I10: ='FH Landed (Prime)'!C12 -> 222632.61
A12: 20-YEAR LIQUID PORTFOLIO GROWTH
A13: Year | B13: Age | C13: HDB Liquid Portfolio | D13: Condo Liquid Portfolio | E13: FH Liquid Portfolio | F13: No Property Full Portfolio | G13: HDB 2005 Liquid Portfolio | H13: HDB 2015 Liquid Portfolio | I13: FH Landed Liquid Portfolio
A14: 0 | B14: =Assumptions!C4 -> 32 | C14: =$C$8 -> 537800 | D14: =$D$8 -> 186800 | E14: =$E$8 -> -261200 | F14: =Assumptions!C7 -> 800000 | G14: =$G$8 -> 727800 | H14: =$H$8 -> 537800 | I14: =$I$8 -> -1253200
A15: =A14+1 -> 1 | B15: =B14+1 -> 33 | C15: =C14*(1+$C$9)-$C$10 -> 516936.2 | D15: =D14*(1+$D$9)-$D$10 -> 117562.36 | E15: =E14*(1+$E$9)-$E$10 -> -399604.17 | F15: =F14*(1+Assumptions!$C$54) -> 844000 | G15: =G14*(1+$G$9)-$G$10 -> 739725.15 | H15: =H14*(1+$H$9)-$H$10 -> 516936.2 | I15: =I14*(1+$I$9)-$I$10 -> -1544758.6
A16: =A15+1 -> 2 | B16: =B15+1 -> 34 | C16: =C15*(1+$C$9)-$C$10 -> 494924.88 | D16: =D15*(1+$D$9)-$D$10 -> 44516.64 | E16: =E15*(1+$E$9)-$E$10 -> -545620.56 | F16: =F15*(1+Assumptions!$C$54) -> 890420 | G16: =G15*(1+$G$9)-$G$10 -> 752306.19 | H16: =H15*(1+$H$9)-$H$10 -> 494924.88 | I16: =I15*(1+$I$9)-$I$10 -> -1852352.9
A17: =A16+1 -> 3 | B17: =B16+1 -> 35 | C17: =C16*(1+$C$9)-$C$10 -> 471702.95 | D17: =D16*(1+$D$9)-$D$10 -> -32546.59 | E17: =E16*(1+$E$9)-$E$10 -> -699667.86 | F17: =F16*(1+Assumptions!$C$54) -> 939393.1 | G17: =G16*(1+$G$9)-$G$10 -> 765579.18 | H17: =H16*(1+$H$9)-$H$10 -> 471702.95 | I17: =I16*(1+$I$9)-$I$10 -> -2176865
A18: =A17+1 -> 4 | B18: =B17+1 -> 36 | C18: =C17*(1+$C$9)-$C$10 -> 447203.81 | D18: =D17*(1+$D$9)-$D$10 -> -113848.3 | E18: =E17*(1+$E$9)-$E$10 -> -862187.76 | F18: =F17*(1+Assumptions!$C$54) -> 991059.72 | G18: =G17*(1+$G$9)-$G$10 -> 779582.19 | H18: =H17*(1+$H$9)-$H$10 -> 447203.81 | I18: =I17*(1+$I$9)-$I$10 -> -2519225.1
A19: =A18+1 -> 5 | B19: =B18+1 -> 37 | C19: =C18*(1+$C$9)-$C$10 -> 421357.21 | D19: =D18*(1+$D$9)-$D$10 -> -199621.6 | E19: =E18*(1+$E$9)-$E$10 -> -1033646.2 | F19: =F18*(1+Assumptions!$C$54) -> 1045568 | G19: =G18*(1+$G$9)-$G$10 -> 794355.36 | H19: =H18*(1+$H$9)-$H$10 -> 421357.21 | I19: =I18*(1+$I$9)-$I$10 -> -2880415.1
A20: =A19+1 -> 6 | B20: =B19+1 -> 38 | C20: =C19*(1+$C$9)-$C$10 -> 394089.06 | D20: =D19*(1+$D$9)-$D$10 -> -290112.43 | E20: =E19*(1+$E$9)-$E$10 -> -1214535 | F20: =F19*(1+Assumptions!$C$54) -> 1103074.2 | G20: =G19*(1+$G$9)-$G$10 -> 809941.06 | H20: =H19*(1+$H$9)-$H$10 -> 394089.06 | I20: =I19*(1+$I$9)-$I$10 -> -3261470.6
A21: =A20+1 -> 7 | B21: =B20+1 -> 39 | C21: =C20*(1+$C$9)-$C$10 -> 365321.15 | D21: =D20*(1+$D$9)-$D$10 -> -385580.26 | E21: =E20*(1+$E$9)-$E$10 -> -1405372.5 | F21: =F20*(1+Assumptions!$C$54) -> 1163743.3 | G21: =G20*(1+$G$9)-$G$10 -> 826383.97 | H21: =H20*(1+$H$9)-$H$10 -> 365321.15 | I21: =I20*(1+$I$9)-$I$10 -> -3663484
A22: =A21+1 -> 8 | B22: =B21+1 -> 40 | C22: =C21*(1+$C$9)-$C$10 -> 334971.01 | D22: =D21*(1+$D$9)-$D$10 -> -486298.82 | E22: =E21*(1+$E$9)-$E$10 -> -1606706.2 | F22: =F21*(1+Assumptions!$C$54) -> 1227749.2 | G22: =G21*(1+$G$9)-$G$10 -> 843731.24 | H22: =H21*(1+$H$9)-$H$10 -> 334971.01 | I22: =I21*(1+$I$9)-$I$10 -> -4087608.3
A23: =A22+1 -> 9 | B23: =B22+1 -> 41 | C23: =C22*(1+$C$9)-$C$10 -> 302951.61 | D23: =D22*(1+$D$9)-$D$10 -> -592556.9 | E23: =E22*(1+$E$9)-$E$10 -> -1819113.2 | F23: =F22*(1+Assumptions!$C$54) -> 1295275.4 | G23: =G22*(1+$G$9)-$G$10 -> 862032.61 | H23: =H22*(1+$H$9)-$H$10 -> 302951.61 | I23: =I22*(1+$I$9)-$I$10 -> -4535059.3
A24: =A23+1 -> 10 | B24: =B23+1 -> 42 | C24: =C23*(1+$C$9)-$C$10 -> 269171.15 | D24: =D23*(1+$D$9)-$D$10 -> -704659.17 | E24: =E23*(1+$E$9)-$E$10 -> -2043202.6 | F24: =F23*(1+Assumptions!$C$54) -> 1366515.6 | G24: =G23*(1+$G$9)-$G$10 -> 881340.55 | H24: =H23*(1+$H$9)-$H$10 -> 269171.15 | I24: =I23*(1+$I$9)-$I$10 -> -5007120.2
A25: =A24+1 -> 11 | B25: =B24+1 -> 43 | C25: =C24*(1+$C$9)-$C$10 -> 233532.76 | D25: =D24*(1+$D$9)-$D$10 -> -822927.07 | E25: =E24*(1+$E$9)-$E$10 -> -2279616.9 | F25: =F24*(1+Assumptions!$C$54) -> 1441673.9 | G25: =G24*(1+$G$9)-$G$10 -> 901710.44 | H25: =H24*(1+$H$9)-$H$10 -> 233532.76 | I25: =I24*(1+$I$9)-$I$10 -> -5505144.4
A26: =A25+1 -> 12 | B26: =B25+1 -> 44 | C26: =C25*(1+$C$9)-$C$10 -> 195934.25 | D26: =D25*(1+$D$9)-$D$10 -> -947699.71 | E26: =E25*(1+$E$9)-$E$10 -> -2529034 | F26: =F25*(1+Assumptions!$C$54) -> 1520966 | G26: =G25*(1+$G$9)-$G$10 -> 923200.66 | H26: =H25*(1+$H$9)-$H$10 -> 195934.25 | I26: =I25*(1+$I$9)-$I$10 -> -6030560
... A34: =A33+1 -> 20 | B34: =B33+1 -> 52 | C34: =C33*(1+$C$9)-$C$10 -> -189685.74 | D34: =D33*(1+$D$9)-$D$10 -> -2227400.2 | E34: =E33*(1+$E$9)-$E$10 -> -5087120.5 | F34: =F33*(1+Assumptions!$C$54) -> 2334206 | G34: =G33*(1+$G$9)-$G$10 -> 1143610 | H34: =H33*(1+$H$9)-$H$10 -> -189685.74 | I34: =I33*(1+$I$9)-$I$10 -> -11419358
A36: TERMINAL NET WORTH COMPARISON (YEAR 20)
C37: HDB 1984 | D37: Condo 99LH | E37: FH Condo | F37: No Property | G37: HDB 2005 | H37: HDB 2015 | I37: FH Landed
A38: Liquid Portfolio (Year 20) | C38: =C34 -> -189685.74 | D38: =D34 -> -2227400.2 | E38: =E34 -> -5087120.5 | F38: =F34 -> 2334206 | G38: =G34 -> 1143610 | H38: =H34 -> -189685.74 | I38: =I34 -> -11419358
A39: Property Equity (Net of CPF) | C39: ='HDB 1984'!Q35 -> 872887.87 | D39: ='Condo 99LH'!Q35 -> 2979508.9 | E39: ='FH Condo'!Q35 -> 7212238.5 | F39: 0 | G39: ='HDB 2005'!Q35 -> 728542.06 | H39: ='HDB 2015'!Q35 -> 1531984.7 | I39: ='FH Landed (Prime)'!Q35 -> 16332551
A40: TOTAL NET WORTH | C40: =C38+C39 -> 683202.13 | D40: =D38+D39 -> 752108.73 | E40: =E38+E39 -> 2125118.1 | F40: =F38+F39 -> 2334206 | G40: =G38+G39 -> 1872152.1 | H40: =H38+H39 -> 1342299 | I40: =I38+I39 -> 4913192.7
A41: NW vs. No Property | C41: =C40-F40 -> -1651003.9 | D41: =D40-F40 -> -1582097.3 | E41: =E40-F40 -> -209087.94 | F41: - | G41: =G40-F40 -> -462053.93 | H41: =H40-F40 -> -991906.99 | I41: =I40-F40 -> 2578986.7
A42: NW CAGR (20yr) | C42: =(C40/Assumptions!C7)^(1/20)-1 -> -0.0078599961 | D42: =(D40/Assumptions!C7)^(1/20)-1 -> -0.0030817831 | E42: =(E40/Assumptions!C7)^(1/20)-1 -> 0.050061302 | F42: =(F40/Assumptions!C7)^(1/20)-1 -> 0.055 | G42: =(G40/Assumptions!C7)^(1/20)-1 -> 0.043428168 | H42: =(H40/Assumptions!C7)^(1/20)-1 -> 0.026214068 | I42: =(I40/Assumptions!C7)^(1/20)-1 -> 0.094998919
A44: ADVANCED PERFORMANCE METRICS
C45: HDB 1984 | D45: Condo 99LH | E45: FH Condo | F45: No Property | G45: HDB 2005 | H45: HDB 2015 | I45: FH Landed
A46: Annualized ROE on Equity | C46: ='HDB 1984'!I40 -> 0.048579418 | D46: ='Condo 99LH'!I40 -> 0.073812702 | E46: ='FH Condo'!I40 -> 0.094742578 | F46: - | G46: ='HDB 2005'!I40 -> 0.073631354 | H46: ='HDB 2015'!I40 -> 0.074152745 | I46: ='FH Landed (Prime)'!I40 -> 0.1059952
A47: Leverage Amplification (ROE ÷ Land Appr.) | C47: =C46/Assumptions!C34 -> 2.4289709 | D47: =D46/Assumptions!D34 -> 2.4604234 | E47: =E46/Assumptions!E34 -> 2.3685645 | F47: - | G47: =G46/Assumptions!F34 -> 2.4543785 | H47: =H46/Assumptions!G34 -> 2.4717582 | I47: =I46/Assumptions!H34 -> 2.119904
A48: Real NW CAGR (Inflation-Adj) | C48: =C42-Assumptions!C43 -> -0.032859996 | D48: =D42-Assumptions!C43 -> -0.028081783 | E48: =E42-Assumptions!C43 -> 0.025061302 | F48: =F42-Assumptions!C43 -> 0.03 | G48: =G42-Assumptions!C43 -> 0.018428168 | H48: =H42-Assumptions!C43 -> 0.0012140681 | I48: =I42-Assumptions!C43 -> 0.069998919
A49: Equity Multiple (Terminal / Day-1) | C49: =C39/'HDB 1984'!C10 -> 2.1176319 | D49: =D39/'Condo 99LH'!C10 -> 3.9039687 | E49: =E39/'FH Condo'!C10 -> 5.9546223 | F49: - | G49: =G39/'HDB 2005'!C10 -> 3.2787672 | H49: =H39/'HDB 2015'!C10 -> 3.7166054 | I49: =I39/'FH Landed (Prime)'!C10 -> 7.4131041
A51: 🏆 WINNER BY METRIC
A52: Highest Total NW | C52: =IF(C40=MAX(C40,D40,E40,F40,G40,H40,I40),"⭐","") | D52: =IF(D40=MAX(C40,D40,E40,F40,G40,H40,I40),"⭐","") | E52: =IF(E40=MAX(C40,D40,E40,F40,G40,H40,I40),"⭐","") | F52: =IF(F40=MAX(C40,D40,E40,F40,G40,H40,I40),"⭐","") | G52: =IF(G40=MAX(C40,D40,E40,F40,G40,H40,I40),"⭐","") | H52: =IF(H40=MAX(C40,D40,E40,F40,G40,H40,I40),"⭐","") | I52: =IF(I40=MAX(C40,D40,E40,F40,G40,H40,I40),"⭐","") -> ⭐
...

Sheet Bala Table
A1: Remaining Lease (Years) | B1: % of Freehold Value | C1: Source: SLA Bala's Table | D1: Lending Restriction | E1: End-of-Horizon Restriction
A2: 99 | B2: 0.9 | D2: =IF(A2<20,"🚫 No bank financing",IF(A2<30,"⚠️ Very restricted; max 60% LTV",IF(A2<(95-Assumptions!$C$4),"⚠️ Tenure capped (loan+age ≤ lease)","✅ Standard lending"))) -> ✅ Standard lending | E2: =IF((A2-Assumptions!$C$5)<0,"🚫 Lease expired within horizon",IF((A2-Assumptions!$C$5)<20,"🚫 No bank financing",IF((A2-Assumptions!$C$5)<30,"⚠️ Very restricted; max 60% LTV",IF((A2-Assumptions!$C$5)<(95-(Assumptions!$C$4+Assumptions!$C$5)),"⚠️ Tenure capped (loan+age ≤ lease)","✅ Standard lending")))) -> ✅ Standard lending
A3: 98 | B3: 0.895 | D3: =IF(A3<20,"🚫 No bank financing",IF(A3<30,"⚠️ Very restricted; max 60% LTV",IF(A3<(95-Assumptions!$C$4),"⚠️ Tenure capped (loan+age ≤ lease)","✅ Standard lending"))) -> ✅ Standard lending | E3: =IF((A3-Assumptions!$C$5)<0,"🚫 Lease expired within horizon",IF((A3-Assumptions!$C$5)<20,"🚫 No bank financing",IF((A3-Assumptions!$C$5)<30,"⚠️ Very restricted; max 60% LTV",IF((A3-Assumptions!$C$5)<(95-(Assumptions!$C$4+Assumptions!$C$5)),"⚠️ Tenure capped (loan+age ≤ lease)","✅ Standard lending")))) -> ✅ Standard lending
A4: 97 | B4: 0.89 | D4: =IF(A4<20,"🚫 No bank financing",IF(A4<30,"⚠️ Very restricted; max 60% LTV",IF(A4<(95-Assumptions!$C$4),"⚠️ Tenure capped (loan+age ≤ lease)","✅ Standard lending"))) -> ✅ Standard lending | E4: =IF((A4-Assumptions!$C$5)<0,"🚫 Lease expired within horizon",IF((A4-Assumptions!$C$5)<20,"🚫 No bank financing",IF((A4-Assumptions!$C$5)<30,"⚠️ Very restricted; max 60% LTV",IF((A4-Assumptions!$C$5)<(95-(Assumptions!$C$4+Assumptions!$C$5)),"⚠️ Tenure capped (loan+age ≤ lease)","✅ Standard lending")))) -> ✅ Standard lending
A5: 96 | B5: 0.885 | D5: =IF(A5<20,"🚫 No bank financing",IF(A5<30,"⚠️ Very restricted; max 60% LTV",IF(A5<(95-Assumptions!$C$4),"⚠️ Tenure capped (loan+age ≤ lease)","✅ Standard lending"))) -> ✅ Standard lending | E5: =IF((A5-Assumptions!$C$5)<0,"🚫 Lease expired within horizon",IF((A5-Assumptions!$C$5)<20,"🚫 No bank financing",IF((A5-Assumptions!$C$5)<30,"⚠️ Very restricted; max 60% LTV",IF((A5-Assumptions!$C$5)<(95-(Assumptions!$C$4+Assumptions!$C$5)),"⚠️ Tenure capped (loan+age ≤ lease)","✅ Standard lending")))) -> ✅ Standard lending
A6: 95 | B6: 0.88 | D6: =IF(A6<20,"🚫 No bank financing",IF(A6<30,"⚠️ Very restricted; max 60% LTV",IF(A6<(95-Assumptions!$C$4),"⚠️ Tenure capped (loan+age ≤ lease)","✅ Standard lending"))) -> ✅ Standard lending | E6: =IF((A6-Assumptions!$C$5)<0,"🚫 Lease expired within horizon",IF((A6-Assumptions!$C$5)<20,"🚫 No bank financing",IF((A6-Assumptions!$C$5)<30,"⚠️ Very restricted; max 60% LTV",IF((A6-Assumptions!$C$5)<(95-(Assumptions!$C$4+Assumptions!$C$5)),"⚠️ Tenure capped (loan+age ≤ lease)","✅ Standard lending")))) -> ✅ Standard lending
A7: 94 | B7: 0.875 | D7: =IF(A7<20,"🚫 No bank financing",IF(A7<30,"⚠️ Very restricted; max 60% LTV",IF(A7<(95-Assumptions!$C$4),"⚠️ Tenure capped (loan+age ≤ lease)","✅ Standard lending"))) -> ✅ Standard lending | E7: =IF((A7-Assumptions!$C$5)<0,"🚫 Lease expired within horizon",IF((A7-Assumptions!$C$5)<20,"🚫 No bank financing",IF((A7-Assumptions!$C$5)<30,"⚠️ Very restricted; max 60% LTV",IF((A7-Assumptions!$C$5)<(95-(Assumptions!$C$4+Assumptions!$C$5)),"⚠️ Tenure capped (loan+age ≤ lease)","✅ Standard lending")))) -> ✅ Standard lending
A8: 93 | B8: 0.87 | D8: =IF(A8<20,"🚫 No bank financing",IF(A8<30,"⚠️ Very restricted; max 60% LTV",IF(A8<(95-Assumptions!$C$4),"⚠️ Tenure capped (loan+age ≤ lease)","✅ Standard lending"))) -> ✅ Standard lending | E8: =IF((A8-Assumptions!$C$5)<0,"🚫 Lease expired within horizon",IF((A8-Assumptions!$C$5)<20,"🚫 No bank financing",IF((A8-Assumptions!$C$5)<30,"⚠️ Very restricted; max 60% LTV",IF((A8-Assumptions!$C$5)<(95-(Assumptions!$C$4+Assumptions!$C$5)),"⚠️ Tenure capped (loan+age ≤ lease)","✅ Standard lending")))) -> ✅ Standard lending
A9: 92 | B9: 0.865 | D9: =IF(A9<20,"🚫 No bank financing",IF(A9<30,"⚠️ Very restricted; max 60% LTV",IF(A9<(95-Assumptions!$C$4),"⚠️ Tenure capped (loan+age ≤ lease)","✅ Standard lending"))) -> ✅ Standard lending | E9: =IF((A9-Assumptions!$C$5)<0,"🚫 Lease expired within horizon",IF((A9-Assumptions!$C$5)<20,"🚫 No bank financing",IF((A9-Assumptions!$C$5)<30,"⚠️ Very restricted; max 60% LTV",IF((A9-Assumptions!$C$5)<(95-(Assumptions!$C$4+Assumptions!$C$5)),"⚠️ Tenure capped (loan+age ≤ lease)","✅ Standard lending")))) -> ✅ Standard lending
A10: 91 | B10: 0.855 | D10: =IF(A10<20,"🚫 No bank financing",IF(A10<30,"⚠️ Very restricted; max 60% LTV",IF(A10<(95-Assumptions!$C$4),"⚠️ Tenure capped (loan+age ≤ lease)","✅ Standard lending"))) -> ✅ Standard lending | E10: =IF((A10-Assumptions!$C$5)<0,"🚫 Lease expired within horizon",IF((A10-Assumptions!$C$5)<20,"🚫 No bank financing",IF((A10-Assumptions!$C$5)<30,"⚠️ Very restricted; max 60% LTV",IF((A10-Assumptions!$C$5)<(95-(Assumptions!$C$4+Assumptions!$C$5)),"⚠️ Tenure capped (loan+age ≤ lease)","✅ Standard lending")))) -> ✅ Standard lending
A11: 90 | B11: 0.85 | D11: =IF(A11<20,"🚫 No bank financing",IF(A11<30,"⚠️ Very restricted; max 60% LTV",IF(A11<(95-Assumptions!$C$4),"⚠️ Tenure capped (loan+age ≤ lease)","✅ Standard lending"))) -> ✅ Standard lending | E11: =IF((A11-Assumptions!$C$5)<0,"🚫 Lease expired within horizon",IF((A11-Assumptions!$C$5)<20,"🚫 No bank financing",IF((A11-Assumptions!$C$5)<30,"⚠️ Very restricted; max 60% LTV",IF((A11-Assumptions!$C$5)<(95-(Assumptions!$C$4+Assumptions!$C$5)),"⚠️ Tenure capped (loan+age ≤ lease)","✅ Standard lending")))) -> ✅ Standard lending
A12: 89 | B12: 0.845 | D12: =IF(A12<20,"🚫 No bank financing",IF(A12<30,"⚠️ Very restricted; max 60% LTV",IF(A12<(95-Assumptions!$C$4),"⚠️ Tenure capped (loan+age ≤ lease)","✅ Standard lending"))) -> ✅ Standard lending | E12: =IF((A12-Assumptions!$C$5)<0,"🚫 Lease expired within horizon",IF((A12-Assumptions!$C$5)<20,"🚫 No bank financing",IF((A12-Assumptions!$C$5)<30,"⚠️ Very restricted; max 60% LTV",IF((A12-Assumptions!$C$5)<(95-(Assumptions!$C$4+Assumptions!$C$5)),"⚠️ Tenure capped (loan+age ≤ lease)","✅ Standard lending")))) -> ✅ Standard lending
A13: 88 | B13: 0.84 | D13: =IF(A13<20,"🚫 No bank financing",IF(A13<30,"⚠️ Very restricted; max 60% LTV",IF(A13<(95-Assumptions!$C$4),"⚠️ Tenure capped (loan+age ≤ lease)","✅ Standard lending"))) -> ✅ Standard lending | E13: =IF((A13-Assumptions!$C$5)<0,"🚫 Lease expired within horizon",IF((A13-Assumptions!$C$5)<20,"🚫 No bank financing",IF((A13-Assumptions!$C$5)<30,"⚠️ Very restricted; max 60% LTV",IF((A13-Assumptions!$C$5)<(95-(Assumptions!$C$4+Assumptions!$C$5)),"⚠️ Tenure capped (loan+age ≤ lease)","✅ Standard lending")))) -> ✅ Standard lending
... A101: 0 | B101: 0 | D101: =IF(A101<20,"🚫 No bank financing",IF(A101<30,"⚠️ Very restricted; max 60% LTV",IF(A101<(95-Assumptions!$C$4),"⚠️ Tenure capped (loan+age ≤ lease)","✅ Standard lending"))) -> 🚫 No bank financing | E101: =IF((A101-Assumptions!$C$5)<0,"🚫 Lease expired within horizon",IF((A101-Assumptions!$C$5)<20,"🚫 No bank financing",IF((A101-Assumptions!$C$5)<30,"⚠️ Very restricted; max 60% LTV",IF((A101-Assumptions!$C$5)<(95-(Assumptions!$C$4+Assumptions!$C$5)),"⚠️ Tenure capped (loan+age ≤ lease)","✅ Standard lending")))) -> 🚫 Lease expired within horizon

Sheet HDB 1984
A1: HDB 1984 — LEVERAGED PROPERTY ANALYSIS
A3: CAPITAL STRUCTURE
A4: Purchase Price | C4: =Assumptions!C31 -> 1400000
A5: Loan Amount (75% LTV) | C5: =Assumptions!C22*Assumptions!C31 -> 1050000
A6: Cash Downpayment | C6: =Assumptions!C23*Assumptions!C31-C7 -> 200000
A7: CPF OA Used | C7: =MIN(Assumptions!C24*Assumptions!C31,Assumptions!C8) -> 150000
A8: Total Upfront Costs | C8: =Assumptions!C51 -> 62200
A9: Total Cash Outlay (Day 1) | C9: =C6+C8 -> 262200
A10: Total Equity at Risk (Cash + CPF) | C10: =C6+C7+C8 -> 412200
A11: Monthly Mortgage Payment | C11: =PMT('Scenario Tables'!C$27/12,Assumptions!C26*12,-C5) -> 4203.567
A12: Annual Mortgage Payment | C12: =C11*12 -> 50442.804
A14: Year | B14: Age | C14: Remaining Lease | D14: Bala Factor (%FH) | E14: FH Equiv. Land Value | F14: Leasehold Market Value | G14: Loan Balance | H14: Property Equity | I14: Annual Interest | J14: Annual Principal | K14: Rent / Imputed Rent (Annual) | L14: Maintenance + Prop Tax (+Mgmt) | M14: Net Holding Benefit (After Tax) | N14: Cumulative Net Benefit | O14: ROE on Equity (%) | P14: CPF Accrued Interest | Q14: Net Equity After CPF | R14: Real Cumul. Net Benefit | S14: Real ROE (CAGR %)
A15: 0 | B15: =Assumptions!C4 -> 32 | C15: =Assumptions!C33 -> 57 | D15: =VLOOKUP(C15,'Bala Table'!A:B,2,FALSE) -> 0.64 | E15: =C4/D15 -> 2187500 | F15: =C4 -> 1400000 | G15: =C5 -> 1050000 | H15: =F15-G15 -> 350000 | I15: - | J15: - | K15: - | L15: - | M15: - | N15: - | O15: - | P15: 0 | Q15: =H15-P15 -> 350000 | R15: - | S15: -
A16: =A15+1 -> 1 | B16: =B15+1 -> 33 | C16: =C15-1 -> 56 | D16: =VLOOKUP(C16,'Bala Table'!$A:$B,2,FALSE) -> 0.632 | E16: =E15*(1+Assumptions!$C$34) -> 2231250 | F16: =E16*D16 -> 1410150 | G16: =IF(A16<=Assumptions!$C$26,PV('Scenario Tables'!C$27/12,(Assumptions!$C$26-A16)*12,-$C$11),0) -> 1026579.4 | H16: =F16-G16 -> 383570.59 | I16: =IF(A16<=Assumptions!$C$26,G15*'Scenario Tables'!C$27,0) -> 27300 | J16: =IF(A16<=Assumptions!$C$26,$C$12-I16,0) -> 23142.804 | K16: =IF(Assumptions!$C$39="Investment",Assumptions!$C$35*12*(1+Assumptions!$C$36)^(A16-1)*(1-Assumptions!$C$40),Assumptions!$C$35*12*(1+Assumptions!$C$36)^(A16-1)) -> 54000 | L16: =IF(Assumptions!$C$39="Investment",_xlfn.LET(_xlpm.gr,Assumptions!$C$35*12*(1+Assumptions!$C$36)^(A16-1),Assumptions!$C$37*(1+Assumptions!$C$36)^(A16-1)+MIN(_xlpm.gr,30000)*0.12+MAX(0,MIN(_xlpm.gr,45000)-30000)*0.2+MAX(0,MIN(_xlpm.gr,60000)-45000)*0.28+MAX(0,_xlpm.gr-60000)*0.36+K16*Assumptions!$C$41),Assumptions!$C$37*(1+Assumptions!$C$36)^(A16-1)+MAX(0,MIN(K16,25000)-12000)*0.04+MAX(0,MIN(K16,38000)-25000)*0.06+MAX(0,MIN(K16,50000)-38000)*0.08+MAX(0,MIN(K16,65000)-50000)*0.1+MAX(0,MIN(K16,80000)-65000)*0.12+MAX(0,MIN(K16,95000)-80000)*0.14+MAX(0,MIN(K16,110000)-95000)*0.16+MAX(0,K16-110000)*0.23) -> 3740 | M16: =IF(Assumptions!$C$39="Investment",(K16-I16-L16)*(1-Assumptions!$C$42),K16-I16-L16) -> 22960 | N16: =IF(A16=1,M16,N15+M16) -> 22960 | O16: =(H16-$C$10)/$C$10 -> -0.069455143 | P16: =Assumptions!$C$8*(1+Assumptions!$C$9)^A16-Assumptions!$C$8+$C$7*((1+Assumptions!$C$9)^A16-1) -> 7500 | Q16: =H16-P16 -> 376070.59 | R16: =N16/(1+Assumptions!$C$43)^A16 -> 22400 | S16: =((H16/$C$10)^(1/A16))/(1+Assumptions!$C$43)-1 -> -0.092151359
A17: =A16+1 -> 2 | B17: =B16+1 -> 34 | C17: =C16-1 -> 55 | D17: =VLOOKUP(C17,'Bala Table'!$A:$B,2,FALSE) -> 0.624 | E17: =E16*(1+Assumptions!$C$34) -> 2275875 | F17: =E17*D17 -> 1420146 | G17: =IF(A17<=Assumptions!$C$26,PV('Scenario Tables'!C$27/12,(Assumptions!$C$26-A17)*12,-$C$11),0) -> 1002542.6 | H17: =F17-G17 -> 417603.43 | I17: =IF(A17<=Assumptions!$C$26,G16*'Scenario Tables'!C$27,0) -> 26691.065 | J17: =IF(A17<=Assumptions!$C$26,$C$12-I17,0) -> 23751.739 | K17: =IF(Assumptions!$C$39="Investment",Assumptions!$C$35*12*(1+Assumptions!$C$36)^(A17-1)*(1-Assumptions!$C$40),Assumptions!$C$35*12*(1+Assumptions!$C$36)^(A17-1)) -> 55080 | L17: =IF(Assumptions!$C$39="Investment",_xlfn.LET(_xlpm.gr,Assumptions!$C$35*12*(1+Assumptions!$C$36)^(A17-1),Assumptions!$C$37*(1+Assumptions!$C$36)^(A17-1)+MIN(_xlpm.gr,30000)*0.12+MAX(0,MIN(_xlpm.gr,45000)-30000)*0.2+MAX(0,MIN(_xlpm.gr,60000)-45000)*0.28+MAX(0,_xlpm.gr-60000)*0.36+K17*Assumptions!$C$41),Assumptions!$C$37*(1+Assumptions!$C$36)^(A17-1)+MAX(0,MIN(K17,25000)-12000)*0.04+MAX(0,MIN(K17,38000)-25000)*0.06+MAX(0,MIN(K17,50000)-38000)*0.08+MAX(0,MIN(K17,65000)-50000)*0.1+MAX(0,MIN(K17,80000)-65000)*0.12+MAX(0,MIN(K17,95000)-80000)*0.14+MAX(0,MIN(K17,110000)-95000)*0.16+MAX(0,K17-110000)*0.23) -> 3869.6 | M17: =IF(Assumptions!$C$39="Investment",(K17-I17-L17)*(1-Assumptions!$C$42),K17-I17-L17) -> 24519.335 | N17: =IF(A17=1,M17,N16+M17) -> 47479.335 | O17: =(H17-$C$10)/$C$10 -> 0.013108746 | P17: =Assumptions!$C$8*(1+Assumptions!$C$9)^A17-Assumptions!$C$8+$C$7*((1+Assumptions!$C$9)^A17-1) -> 15187.5 | Q17: =H17-P17 -> 402415.93 | R17: =N17/(1+Assumptions!$C$43)^A17 -> 45191.515 | S17: =((H17/$C$10)^(1/A17))/(1+Assumptions!$C$43)-1 -> -0.018016554
